<?xml version="1.0" ?>

<sdf version="1.5">
  <model name="basic_mobile_bot">  
  <static>false</static>

  <!-- ****************** ROBOT BASE FOOTPRINT ***************************  -->
  <pose>0.0 0.0 0.0 0.0 0.0 0.0</pose>
  <link name="base_footprint"/>

  <!-- ********************** ROBOT BASE *********************************  -->
  <link name="base_link">

    <collision name="base_collision">
      <pose>0 0 0.1 0 0 0</pose>
      <geometry>
        <box>
          <size>0.70 0.39 0.20</size>
        </box>
      </geometry>
    </collision>

    <visual name="base_visual">
      <pose>0 0 -0.05 1.5707963267949 0 3.141592654</pose>
      <geometry>
        <mesh>
          <uri>model://basic_mobile_bot_description/meshes/robot_base.stl</uri>
          <scale>1.0 1.0 1.0</scale>
        </mesh>
      </geometry>
      <material>
        <ambient>1.0 0.0 0.0 1.0</ambient>
        <diffuse>1.0 0.0 0.0 1.0</diffuse>
        <specular>0.0 0.0 0.0 1.0</specular>
        <emissive>0.0 0.0 0.0 1.0</emissive>
      </material>
    </visual>
  </link>

  <!-- *********************** IMU SENSOR SETUP **************************  -->
  <link name="imu_link">
      <sensor name="tb3_imu" type="imu">
        <always_on>true</always_on>
        <update_rate>200</update_rate>
        <visualize>true</visualize>
        <imu>
          <angular_velocity>
            <x>
              <noise type="gaussian">
                <mean>0.0</mean>
                <stddev>2e-4</stddev>
              </noise>
            </x>
            <y>
              <noise type="gaussian">
                <mean>0.0</mean>
                <stddev>2e-4</stddev>
              </noise>
            </y>
            <z>
              <noise type="gaussian">
                <mean>0.0</mean>
                <stddev>2e-4</stddev>
              </noise>
            </z>
          </angular_velocity>
          <linear_acceleration>
            <x>
              <noise type="gaussian">
                <mean>0.0</mean>
                <stddev>1.7e-2</stddev>
              </noise>
            </x>
            <y>
              <noise type="gaussian">
                <mean>0.0</mean>
                <stddev>1.7e-2</stddev>
              </noise>
            </y>
            <z>
              <noise type="gaussian">
                <mean>0.0</mean>
                <stddev>1.7e-2</stddev>
              </noise>
            </z>
          </linear_acceleration>
        </imu>
        <plugin name="turtlebot3_imu" filename="libgazebo_ros_imu_sensor.so">
          <initial_orientation_as_reference>false</initial_orientation_as_reference>
          <frame_name>imu_link</frame_name>
          <ros>
            <namespace>/imu</namespace>
            <remapping>~/out:=data</remapping>
          </ros>
        </plugin>
      </sensor>
    </link>



<!-- ****************************** Realsense Camera *****************************    -->
  <link name="realsense_link">

      <inertial>
        <pose>0.3 0 0.2 0 0 0</pose>

        <inertia>
          <ixx>0.001</ixx>
          <ixy>0.000</ixy>
          <ixz>0.000</ixz>
          <iyy>0.001</iyy>
          <iyz>0.000</iyz>
          <izz>0.001</izz>
        </inertia>
        <mass>0.035</mass>
      </inertial>

      <collision name="collision">
        <pose>0 0.047 0 0 0 0</pose>
        <geometry>
          <box>
            <size>0.008 0.130 0.022</size>
          </box>
        </geometry>
      </collision>
      <pose>0.3 0 0.2 0 0 0</pose>


      <sensor name="intel_realsense_r200_depth" type="depth">
        <always_on>1</always_on>
        <update_rate>1</update_rate>
        <pose>0 0 0 0 0 0</pose>
        <camera name="realsense_depth_camera">
          <horizontal_fov>1.5</horizontal_fov>
        </camera>


	      <plugin name="intel_realsense_r200_depth_driver" filename="libgazebo_ros_camera.so">
          <ros>
            <imageTopicName>/intel_realsense_r200_depth/color/image_raw</imageTopicName>
            <cameraInfoTopicName>/intel_realsense_r200_depth/color/camera_info</cameraInfoTopicName>
            <depthImageTopicName>/intel_realsense_r200_depth/depth/image_raw</depthImageTopicName>
            <depthImageCameraInfoTopicName>/intel_realsense_r200_depth/depth/camera_info</depthImageCameraInfoTopicName>
            <pointCloudTopicName>/intel_realsense_r200_depth/points</pointCloudTopicName>
            <!-- <remapping >custom_camera/image_raw:=custom_camera/custom_image</remapping>
            <remapping >custom_camera/image_depth:=custom_camera/custom_image_depth</remapping>
            <remapping >custom_camera/camera_info:=custom_camera/custom_info_raw</remapping >
            <remapping >custom_camera/camera_info_depth:=custom_camera/custom_info_depth</remapping >
            <remapping >custom_camera/points:=custom_camera/custom_points</remapping>  -->
          </ros>

          <camera_name>intel_realsense_r200_depth</camera_name>
          <frame_name>realsense_depth_frame</frame_name>
          <hack_baseline>0.07</hack_baseline>
          <min_depth>0.0001</min_depth>
        </plugin>
      </sensor>

  <sensor name="intel_realsense_r200_rgb" type="camera">
      <always_on>true</always_on>
      <visualize>true</visualize>
      <update_rate>30</update_rate>
	    <pose>0 0 0 0 0 0</pose>
      <camera name="realsense_rgb_camera">
          <horizontal_fov>1.5</horizontal_fov>
          <image>
            <width>1920</width>
            <height>1080</height>
            <format>R8G8B8</format>
          </image>
          <clip>
            <near>0.02</near>
            <far>300</far>
          </clip>
          <noise>
            <type>gaussian</type>
            <mean>0.0</mean>
            <stddev>0.007</stddev>
          </noise>
      </camera>
        <plugin name="intel_realsense_r200_rgb_driver" filename="libgazebo_ros_camera.so">
            <ros>
            <!--
              <namespace>custom_ns</namespace>
              <remapping >image_raw:=custom_image</remapping>
              <remapping >camera_info:=custom_info_raw</remapping > 
            -->
            </ros>
            <camera_name>intel_realsense_r200_rgb</camera_name>
            <frame_name>realsense_rgb_frame</frame_name>
            <hack_baseline>0.07</hack_baseline>
        </plugin>
    </sensor>
  </link>  
  


  <!-- *********************** DRIVE WHEELS ******************************  -->
  <link name="drivewhl_l_link">
    <pose>-0.221 0.23 -0.05 0 1.570796 1.570796</pose>
    
    <collision name="drivewhl_l_collision">
      <geometry>
        <cylinder>
          <radius>0.14</radius>
          <length>0.06</length>
        </cylinder>
      </geometry>
    </collision>

    <visual name="drivewhl_l_visual">
      <geometry>
        <cylinder>
          <radius>0.14</radius>
          <length>0.06</length>
        </cylinder>
      </geometry>
    </visual>
  </link>

  <link name="drivewhl_r_link">
    <pose>-0.221 -0.23 -0.05 0 1.570796 1.570796</pose>
    
    <collision name="drivewhl_r_collision">
      <geometry>
        <cylinder>
          <radius>0.14</radius>
          <length>0.06</length>
        </cylinder>
      </geometry>
    </collision>

    <visual name="drivewhl_r_visual">
      <geometry>
        <cylinder>
          <radius>0.14</radius>
          <length>0.06</length>
        </cylinder>
      </geometry>
    </visual>
  </link>

  <!-- *********************** CASTER WHEEL ******************************  -->
  <link name='front_caster'>
    <pose>0.217 0 -0.1 0 0 0</pose>
    <inertial>
      <inertia>
        <ixx>0.001</ixx>
        <ixy>0.000</ixy>
        <ixz>0.000</ixz>
        <iyy>0.001</iyy>
        <iyz>0.000</iyz>
        <izz>0.001</izz>
      </inertia>
      <mass>70.0</mass>
    </inertial>
    <collision name='collision'>
      <geometry>
        <sphere>
          <radius>0.09</radius>
        </sphere>
      </geometry>
      <surface>
        <friction>
          <ode>
            <mu>0.01</mu>
            <mu2>0.01</mu2>
            <slip1>1.0</slip1>
            <slip2>1.0</slip2>
          </ode>
        </friction>
      </surface>
    </collision>
    <visual name="front_caster_visual">
      <geometry>
        <sphere>
          <radius>0.09</radius>
        </sphere>
      </geometry>
    </visual>
  </link>

  <!-- ************************ JOINTS ***********************************  -->
  <!-- Pose of the joint is the same as the child link frame -->
  <!-- Axis is the axis of rotation relative to the child link frame -->
  
  <joint name="base_joint" type="fixed">
    <parent>base_footprint</parent>
    <child>base_link</child>
    <pose>0 0 0 0 0 0</pose>
  </joint>

  <joint name="drivewhl_l_joint" type="revolute">
    <parent>base_link</parent>
    <child>drivewhl_l_link</child>
    <pose>0 0 0 0 0 0</pose>
    <axis>
      <xyz>0 0 1</xyz>
    </axis>
  </joint>

  <joint name="drivewhl_r_joint" type="revolute">
    <parent>base_link</parent>
    <child>drivewhl_r_link</child>
    <pose>0 0 0 0 0 0</pose>
    <axis>
      <xyz>0 0 1</xyz>
    </axis>
  </joint>

  <joint name='caster_joint' type='fixed'>
    <parent>base_link</parent>
    <child>front_caster</child>
    <pose>0 0 0 0 0 0</pose>
  </joint>

  <joint name="imu_joint" type="fixed">
    <parent>base_link</parent>
    <child>imu_link</child>
    <pose>0 0 0 0 0 0</pose>
  </joint>  

  <joint name="lidar_joint" type="fixed">
      <parent>base_link</parent>
      <child>base_scan</child>
      <pose>-0.064 0 0.121 0 0 0</pose>
      <axis>
        <xyz>0 0 1</xyz>
      </axis>
  </joint>
  
 <joint name="camera_joint" type="fixed">
    <parent>base_link</parent>
    <child>realsense_link</child>
    <pose>0 0 0 0 0 0</pose>
  </joint>  

 <!-- *********************** WHEEL ODOMETRY ***************************    -->
  <plugin name="basic_mobile_bot_diff_drive" filename="libgazebo_ros_diff_drive.so">

    <update_rate>30</update_rate>

    <!-- wheels -->
    <left_joint>drivewhl_l_joint</left_joint>
    <right_joint>drivewhl_r_joint</right_joint>

    <!-- kinematics -->
    <wheel_separation>0.52</wheel_separation>
    <wheel_diameter>0.28</wheel_diameter>

    <!-- limits -->
    <max_wheel_torque>20</max_wheel_torque>
    <max_wheel_acceleration>1.0</max_wheel_acceleration>

    <!-- Receive velocity commands on this ROS topic -->
    <command_topic>cmd_vel</command_topic>

    <!-- output -->
    <!-- When false, publish no wheel odometry data to a ROS topic -->
    <publish_odom>true</publish_odom>

    <!-- When true, publish coordinate transform from odom to base_footprint -->
    <!-- I usually use the robot_localization package to publish this transform -->   
    <publish_odom_tf>false</publish_odom_tf>
    
    <!-- When true, publish coordinate transform from base_link to the wheels -->
    <!-- The robot_state_publisher package is often used to publish this transform -->   
    <publish_wheel_tf>false</publish_wheel_tf>

    <odometry_topic>odom</odometry_topic>
    <odometry_frame>odom</odometry_frame>
    <robot_base_frame>base_footprint</robot_base_frame>

    <!-- Odometry source, 0 for ENCODER, 1 for WORLD, defaults to WORLD -->
    <odometry_source>1</odometry_source>

    <!-- Change the ROS topic we will publish the odometry data to -->
    <ros>
      <remapping>odom:=wheel/odometry</remapping>
    </ros>

  </plugin>

 <!-- *********************** JOINT STATE PUBLISHER *********************   -->
  
  <plugin name="basic_mobile_bot_joint_state" filename="libgazebo_ros_joint_state_publisher.so">
    <ros>
      <remapping>~/out:=joint_states</remapping>
    </ros>
    <update_rate>30</update_rate>
    <joint_name>drivewhl_l_joint</joint_name>
    <joint_name>drivewhl_r_joint</joint_name>
  </plugin>   
  
  </model>
</sdf>