<?xml version='1.0'?>
<sdf version='1.5'>
  <model name='atirobot'>
  <static>false</static>

  ****************** ROBOT BASE FOOTPRINT *************************** 
  <pose>0.0 0.0 0.73199 0.0 0.0 0.0</pose>
  <link name="base_footprint"/>

  <link name='base_link'>

    <inertial>
      <mass>20.0</mass>

    </inertial>

    <collision name="base_collision">
      <pose>0 0 0.1 0 0 0</pose>
      <geometry>
        <box>
          <size>0.45 0.665 0.73</size>
        </box>
      </geometry>
    </collision>

    <visual name="base_visual">
    <pose>0 0 0.47 0 0 3.141592654</pose>

      <geometry>
        <mesh>
          <uri>model://ati_bot_description/meshes/base_link.stl</uri>
          <scale>1.0 1.0 1.0</scale>
        </mesh>
      </geometry>
      <material>
        <ambient>1.0 0.0 0.0 1.0</ambient>
        <diffuse>1.0 0.0 0.0 1.0</diffuse>
        <specular>0.0 0.0 0.0 1.0</specular>
        <emissive>0.0 0.0 0.0 1.0</emissive>
      </material>
    </visual>

  </link>

<!-- ****************************** Realsense Camera *****************************    -->
  <link name="realsense_link">

    <inertial>
      <pose>-0.5 0 0.3 0 0 0</pose>


      <inertia>
        <ixx>0.001</ixx>
        <ixy>0.000</ixy>
        <ixz>0.000</ixz>
        <iyy>0.001</iyy>
        <iyz>0.000</iyz>
        <izz>0.001</izz>
      </inertia>
      <mass>0.035</mass>
    </inertial>

    <collision name="collision">
      <pose>0 0.047 0 0 0 0</pose>
      <geometry>
        <box>
          <size>0.008 0.130 0.022</size>
        </box>
      </geometry>
    </collision>
    <pose>-0.5 0 0.3 0 0 0</pose>


    <sensor name="intel_realsense_r200_depth" type="depth">
      <always_on>1</always_on>
      <update_rate>1</update_rate>
      <pose>0 0 0 0 0 3.14159265359</pose>

      <camera name="realsense_depth_camera">
        <horizontal_fov>1.5</horizontal_fov>
      </camera>


      <plugin name="intel_realsense_r200_depth_driver" filename="libgazebo_ros_camera.so">
        <ros>
          <imageTopicName>/intel_realsense_r200_depth/color/image_raw</imageTopicName>
          <cameraInfoTopicName>/intel_realsense_r200_depth/color/camera_info</cameraInfoTopicName>
          <depthImageTopicName>/intel_realsense_r200_depth/depth/image_raw</depthImageTopicName>
          <depthImageCameraInfoTopicName>/intel_realsense_r200_depth/depth/camera_info</depthImageCameraInfoTopicName>
          <pointCloudTopicName>/intel_realsense_r200_depth/points</pointCloudTopicName>
          <!-- <remapping >custom_camera/image_raw:=custom_camera/custom_image</remapping>
          <remapping >custom_camera/image_depth:=custom_camera/custom_image_depth</remapping>
          <remapping >custom_camera/camera_info:=custom_camera/custom_info_raw</remapping >
          <remapping >custom_camera/camera_info_depth:=custom_camera/custom_info_depth</remapping >
          <remapping >custom_camera/points:=custom_camera/custom_points</remapping>  -->
        </ros>

        <camera_name>intel_realsense_r200_depth</camera_name>
        <frame_name>realsense_depth_frame</frame_name>
        <hack_baseline>0.07</hack_baseline>
        <min_depth>0.0001</min_depth>
      </plugin>
    </sensor>

  <sensor name="intel_realsense_r200_rgb" type="camera">
      <always_on>true</always_on>
      <visualize>true</visualize>
      <update_rate>30</update_rate>
      <pose>0 0 0 0 0 3.14159265359</pose>

      <camera name="realsense_rgb_camera">
          <horizontal_fov>1.5</horizontal_fov>
          <image>
            <width>1920</width>
            <height>1080</height>
            <format>R8G8B8</format>
          </image>
          <clip>
            <near>0.02</near>
            <far>300</far>
          </clip>
          <noise>
            <type>gaussian</type>
            <mean>0.0</mean>
            <stddev>0.007</stddev>
          </noise>
      </camera>
        <plugin name="intel_realsense_r200_rgb_driver" filename="libgazebo_ros_camera.so">
            <ros>
            <!--
              <namespace>custom_ns</namespace>
              <remapping >image_raw:=custom_image</remapping>
              <remapping >camera_info:=custom_info_raw</remapping > 
            -->
            </ros>
            <camera_name>intel_realsense_r200_rgb</camera_name>
            <frame_name>realsense_rgb_frame</frame_name>
            <hack_baseline>0.07</hack_baseline>
        </plugin>
    </sensor>
  </link>  
  <!-- *********************** DRIVE WHEELS ******************************  -->


  <link name="drivewhl_l_link">


    <pose>-0.261 0.25 -0.19 0 1.570796 1.570796</pose>
    <inertial>
      <inertia>
        <ixx>0.001</ixx>
        <ixy>0.000</ixy>
        <ixz>0.000</ixz>
        <iyy>0.001</iyy>
        <iyz>0.000</iyz>
        <izz>0.001</izz>
      </inertia>
      <mass>20.0</mass>
    </inertial>
    <!-- <pose>5.55111512312578E-17 -0.0277740369558408 1.38777878078145E-17 0 0 0</pose> -->

    <collision name="drivewhl_l_collision">
      <geometry>
        <cylinder>
          <radius>0.085</radius>
          <length>0.055</length>
        </cylinder>
      </geometry>
    </collision>

    <visual name="drivewhl_l_visual">
      <geometry>
        <cylinder>
          <radius>0.085</radius>
          <length>0.055</length>
        </cylinder>
      </geometry>
    </visual>

</link>

<link name='drivewhl_r_link'>

    <pose>-0.261 -0.25 -0.19 0 1.570796 1.570796</pose>
    <inertial>
      <inertia>
        <ixx>0.001</ixx>
        <ixy>0.000</ixy>
        <ixz>0.000</ixz>
        <iyy>0.001</iyy>
        <iyz>0.000</iyz>
        <izz>0.001</izz>
      </inertia>
      <mass>20.0</mass>
    </inertial>
    <!-- <pose>2.77555756156289E-17 0.0277740369558408 -1.12757025938492E-17 0 0 0</pose> -->

    <collision name="drivewhl_r_collision">
      <geometry>
        <cylinder>
          <radius>0.085</radius>
          <length>0.055</length>
        </cylinder>
      </geometry>
    </collision>

    <visual name="drivewhl_r_visual">
      <geometry>
        <cylinder>
          <radius>0.085</radius>
          <length>0.055</length>
        </cylinder>
      </geometry>
    </visual>

</link>


<!-- *********************** CASTER WHEEL ******************************  -->
  <link name='front_caster'>
    <pose>0.217 0 -0.2 0 0 0</pose>
    <inertial>
      <inertia>
        <ixx>0.001</ixx>
        <ixy>0.000</ixy>
        <ixz>0.000</ixz>
        <iyy>0.001</iyy>
        <iyz>0.000</iyz>
        <izz>0.001</izz>
      </inertia>
      <mass>20.0</mass>
    </inertial>
    <collision name='collision'>
      <geometry>
        <sphere>
          <radius>0.09</radius>
        </sphere>
      </geometry>
      <surface>
        <friction>
          <ode>
            <mu>0.01</mu>
            <mu2>0.01</mu2>
            <slip1>1.0</slip1>
            <slip2>1.0</slip2>
          </ode>
        </friction>
      </surface>
    </collision>
    <visual name="front_caster_visual">
      <geometry>
        <sphere>
          <radius>0.09</radius>
        </sphere>
      </geometry>
    </visual>
  </link>



  <!-- joints -->

  <joint name="base_joint" type="fixed">
    <parent>base_footprint</parent>
    <child>base_link</child>
    <pose>0 0 0 0 0 0</pose>
  </joint>

  <joint name="drivewhl_l_joint" type="revolute">
    <parent>base_link</parent>
    <child>drivewhl_l_link</child>

    <axis>
      <xyz>0 0 -1</xyz>
      <limit>
        <effort>1</effort>
        <velocity>1</velocity>
      </limit>
    </axis>
  </joint>

  <joint name="drivewhl_r_joint" type="revolute">
    <parent>base_link</parent>
    <child>drivewhl_r_link</child>
    <axis>
      <xyz>0 0 -1</xyz>
      <limit>
        <effort>1</effort>
        <velocity>1</velocity>
      </limit>
    </axis>
  </joint>

  <joint name='caster_joint' type='fixed'>
    <parent>base_link</parent>
    <child>front_caster</child>
    <pose>0 0 0 0 0 0</pose>
  </joint>


  <joint name="camera_joint" type="fixed">
    <parent>base_link</parent>
    <child>realsense_link</child>
    <pose>0 0 0 0 0 0</pose>
  </joint>  

  <!-- *********************** WHEEL ODOMETRY ***************************    -->
  <plugin name="basic_mobile_bot_diff_drive" filename="libgazebo_ros_diff_drive.so">

    <update_rate>30</update_rate>

    <!-- wheels -->
    <left_joint>drivewhl_l_joint</left_joint>
    <right_joint>drivewhl_r_joint</right_joint>


    <!-- kinematics -->
    <wheel_separation>0.52</wheel_separation>
    <wheel_diameter>0.28</wheel_diameter>

    <!-- limits -->
    <max_wheel_torque>20</max_wheel_torque>
    <max_wheel_acceleration>1.0</max_wheel_acceleration>

    <!-- Receive velocity commands on this ROS topic -->
    <command_topic>cmd_vel</command_topic>

    <!-- output -->
    <!-- When false, publish no wheel odometry data to a ROS topic -->
    <publish_odom>true</publish_odom>

    <!-- When true, publish coordinate transform from odom to base_footprint -->
    <!-- I usually use the robot_localization package to publish this transform -->   
    <publish_odom_tf>false</publish_odom_tf>
    
    <!-- When true, publish coordinate transform from base_link to the wheels -->
    <!-- The robot_state_publisher package is often used to publish this transform -->   
    <publish_wheel_tf>false</publish_wheel_tf>

    <odometry_topic>odom</odometry_topic>
    <odometry_frame>odom</odometry_frame>
    <robot_base_frame>base_footprint</robot_base_frame>

    <!-- Odometry source, 0 for ENCODER, 1 for base_footprint, defaults to base_footprint -->
    <odometry_source>1</odometry_source>

    <!-- Change the ROS topic we will publish the odometry data to -->
    <ros>
      <remapping>odom:=wheel/odometry</remapping>
    </ros>

  </plugin>

  <!-- *********************** JOINT STATE PUBLISHER *********************   -->
    
  <plugin name="basic_mobile_bot_joint_state" filename="libgazebo_ros_joint_state_publisher.so">
    <ros>
      <remapping>~/out:=joint_states</remapping>
    </ros>
    <update_rate>30</update_rate>
    <joint_name>drivewhl_l_joint</joint_name>
    <joint_name>drivewhl_r_joint</joint_name>
  </plugin> 


  </model>
</sdf>
